Workbook
Name Catergory: 'Accident & Incident Detail'!$I$2
Name Investigationtype: 'Lookup Sheets'!$X$2:$X$8
Name Investigationtype: 'Lookup Sheets'!$X$2:$X$8

Sheet Data
B1: 1 | C1: 1 | D1: 1 | E1: 1 | F1: 1 | G1: 1 | H1: 1 | I1: 1 | J1: 1 | K1: 1 | L1: 1 | M1: 1 | N1: 1 | O1: 1 | P1: 1 | Q1: 1 | R1: 1 | S1: 1 | T1: 1 | U1: 1 | V1: 1 | W1: 1 | X1: 1 | Y1: 1 | Z1: 1 | AA1: 1 | AB1: 1 | AC1: 1 | AD1: 1 | AE1: 1 | AF1: 1 | AG1: 1 | AH1: 1 | AI1: 1 | AJ1: 1 | AK1: 1
A3: Actuals | N3: WK 1
B4: 2301 | C4: 2302 | D4: 2303 | E4: 2304 | F4: 2305 | G4: 2306 | H4: 2307 | I4: 2308 | J4: 2309 | K4: 2310 | L4: 2311 | M4: 2312 | N4: 2313 | O4: 2401 | P4: 2402 | Q4: 2403 | R4: 2404 | S4: 2405 | T4: 2406 | U4: 2407 | V4: 2408 | W4: 2409 | X4: 2410 | Y4: 2411 | Z4: 2412 | AA4: 2413 | AB4: 2501 | AC4: 2502 | AD4: 2503 | AE4: 2504 | AF4: 2505 | AG4: 2506 | AH4: 2507 | AI4: 2508 | AJ4: 2509 | AK4: 2510 | AL4: 2511 | AM4: 2512 | AN4: 2513
B5: {=SUM(($A$6='Accident & Incident Detail'!$I$3:$I$3433)*(Data!B4='Accident & Incident Detail'!$C$3:$C$3433))} -> 0 | C5: {=SUM(($A$6='Accident & Incident Detail'!$I$3:$I$3433)*(Data!C4='Accident & Incident Detail'!$C$3:$C$3433))} -> 0 | D5: {=SUM(($A$6='Accident & Incident Detail'!$I$3:$I$3433)*(Data!D4='Accident & Incident Detail'!$C$3:$C$3433))} -> 0 | E5: {=SUM(($A$6='Accident & Incident Detail'!$I$3:$I$3433)*(Data!E4='Accident & Incident Detail'!$C$3:$C$3433))} -> 0 | F5: {=SUM(($A$6='Accident & Incident Detail'!$I$3:$I$3433)*(Data!F4='Accident & Incident Detail'!$C$3:$C$3433))} -> 0 | G5: {=SUM(($A$6='Accident & Incident Detail'!$I$3:$I$3433)*(Data!G4='Accident & Incident Detail'!$C$3:$C$3433))} -> 0 | H5: {=SUM(($A$6='Accident & Incident Detail'!$I$3:$I$3433)*(Data!H4='Accident & Incident Detail'!$C$3:$C$3433))} -> 0 | I5: {=SUM(($A$6='Accident & Incident Detail'!$I$3:$I$3433)*(Data!I4='Accident & Incident Detail'!$C$3:$C$3433))} -> 0 | ... AA5: {=SUM(($A$6='Accident & Incident Detail'!$I$3:$I$3433)*(Data!AA4='Accident & Incident Detail'!$C$3:$C$3433))} -> 4 | AB5: {=SUM(($A$6='Accident & Incident Detail'!$I$3:$I$3434)*(Data!AB4='Accident & Incident Detail'!$C$3:$C$3434))} -> 4 | AC5: {=SUM(($A$6='Accident & Incident Detail'!$I$3:$I$3433)*(Data!AC4='Accident & Incident Detail'!$C$3:$C$3433))} -> 1 | AD5: {=SUM(($A$6='Accident & Incident Detail'!$I$3:$I$3433)*(Data!AD4='Accident & Incident Detail'!$C$3:$C$3433))} -> 3 | AE5: {=SUM(($A$6='Accident & Incident Detail'!$I$3:$I$3433)*(Data!AE4='Accident & Incident Detail'!$C$3:$C$3433))} -> 2 | AF5: {=SUM(($A$6='Accident & Incident Detail'!$I$3:$I$3433)*(Data!AF4='Accident & Incident Detail'!$C$3:$C$3433))} -> 0 | AG5: {=SUM(($A$6='Accident & Incident Detail'!$I$3:$I$3433)*(Data!AG4='Accident & Incident Detail'!$C$3:$C$3433))} -> 1 | AH5: {=SUM(($A$6='Accident & Incident Detail'!$I$3:$I$3433)*(Data!AH4='Accident & Incident Detail'!$C$3:$C$3433))} -> 4 | AI5: {=SUM(($A$6='Accident & Incident Detail'!$I$3:$I$3433)*(Data!AI4='Accident & Incident Detail'!$C$3:$C$3433))} -> 0 | AJ5: {=SUM(($A$6='Accident & Incident Detail'!$I$3:$I$3433)*(Data!AJ4='Accident & Incident Detail'!$C$3:$C$3433))} -> 4 | ... AN5: {=SUM(($A$6='Accident & Incident Detail'!$I$3:$I$3433)*(Data!AN4='Accident & Incident Detail'!$C$3:$C$3433))} -> 0 | AO5: =SUM(AB5:AN5) -> 24
A6: Staff Accident | B6: =B5-B7 -> 0 | C6: =C5-C7 -> 0 | D6: =D5-D7 -> 0 | E6: =E5-E7 -> -1 | F6: =F5-F7 -> 0 | G6: =G5-G7 -> -1 | H6: =H5-H7 -> 0 | I6: =I5-I7 -> 0 | ... Y6: =Y5-Y7 -> 5 | Z6: {=SUM(($A$6='Accident & Incident Detail'!$I$3:$I$3433)*(Data!Z5='Accident & Incident Detail'!$C$3:$C$3433))} -> 0 | AA6: {=SUM(($A$6='Accident & Incident Detail'!$I$3:$I$3433)*(Data!AA5='Accident & Incident Detail'!$C$3:$C$3433))} -> 0 | AB6: =AB5-AB7 -> 3 | AC6: =AC5-AC7 -> 1 | AD6: =AD5-AD7 -> 3 | AE6: =AE5-AE7 -> 2 | AF6: =AF5-AF7 -> 0 | AG6: =AG5-AG7 -> 1 | AH6: =AH5-AH7 -> 4 | AI6: =AI5-AI7 -> 0 | ... AN6: =AN5-AN7 -> 0 | AO6: =SUM(AB6:AN6) -> 22
A7: Staff LTA | E7: 1 | G7: 1 | P7: 1 | Z7: {=SUM(($A$6='Accident & Incident Detail'!$I$3:$I$3433)*(Data!Z6='Accident & Incident Detail'!$C$3:$C$3433))} -> 0 | AA7: {=SUM(($A$6='Accident & Incident Detail'!$I$3:$I$3433)*(Data!AA6='Accident & Incident Detail'!$C$3:$C$3433))} -> 0 | AB7: 1 | AJ7: 1 | AO7: =SUM(AB7:AN7) -> 2
A8: Assaults | B8: {=SUM(($A$8='Accident & Incident Detail'!$I$3:$I$3433)*(Data!B4='Accident & Incident Detail'!$C$3:$C$3433))} -> 0 | C8: {=SUM(($A$8='Accident & Incident Detail'!$I$3:$I$3433)*(Data!C4='Accident & Incident Detail'!$C$3:$C$3433))} -> 0 | D8: {=SUM(($A$8='Accident & Incident Detail'!$I$3:$I$3433)*(Data!D4='Accident & Incident Detail'!$C$3:$C$3433))} -> 0 | E8: {=SUM(($A$8='Accident & Incident Detail'!$I$3:$I$3433)*(Data!E4='Accident & Incident Detail'!$C$3:$C$3433))} -> 0 | F8: {=SUM(($A$8='Accident & Incident Detail'!$I$3:$I$3433)*(Data!F4='Accident & Incident Detail'!$C$3:$C$3433))} -> 0 | G8: {=SUM(($A$8='Accident & Incident Detail'!$I$3:$I$3433)*(Data!G4='Accident & Incident Detail'!$C$3:$C$3433))} -> 0 | H8: {=SUM(($A$8='Accident & Incident Detail'!$I$3:$I$3433)*(Data!H4='Accident & Incident Detail'!$C$3:$C$3433))} -> 0 | I8: {=SUM(($A$8='Accident & Incident Detail'!$I$3:$I$3433)*(Data!I4='Accident & Incident Detail'!$C$3:$C$3433))} -> 0 | ... Y8: {=SUM(($A$8='Accident & Incident Detail'!$I$3:$I$3433)*(Data!Y4='Accident & Incident Detail'!$C$3:$C$3433))} -> 1 | Z8: {=SUM(($A$6='Accident & Incident Detail'!$I$3:$I$3433)*(Data!Z7='Accident & Incident Detail'!$C$3:$C$3433))} -> 0 | AA8: {=SUM(($A$6='Accident & Incident Detail'!$I$3:$I$3433)*(Data!AA7='Accident & Incident Detail'!$C$3:$C$3433))} -> 0 | AB8: {=SUM(($A$8='Accident & Incident Detail'!$I$3:$I$3433)*(Data!AB7='Accident & Incident Detail'!$C$3:$C$3433))} -> 0 | AC8: {=SUM(($A$8='Accident & Incident Detail'!$I$3:$I$3433)*(Data!AC4='Accident & Incident Detail'!$C$3:$C$3433))} -> 4 | AD8: {=SUM(($A$8='Accident & Incident Detail'!$I$3:$I$3433)*(Data!AD4='Accident & Incident Detail'!$C$3:$C$3433))} -> 6 | AE8: {=SUM(($A$8='Accident & Incident Detail'!$I$3:$I$3433)*(Data!AE4='Accident & Incident Detail'!$C$3:$C$3433))} -> 2 | AF8: {=SUM(($A$8='Accident & Incident Detail'!$I$3:$I$3433)*(Data!AF4='Accident & Incident Detail'!$C$3:$C$3433))} -> 1 | AG8: {=SUM(($A$8='Accident & Incident Detail'!$I$3:$I$3433)*(Data!AG4='Accident & Incident Detail'!$C$3:$C$3433))} -> 1 | AH8: {=SUM(($A$8='Accident & Incident Detail'!$I$3:$I$3433)*(Data!AH4='Accident & Incident Detail'!$C$3:$C$3433))} -> 3 | AI8: {=SUM(($A$8='Accident & Incident Detail'!$I$3:$I$3433)*(Data!AI4='Accident & Incident Detail'!$C$3:$C$3433))} -> 1 | AJ8: {=SUM(($A$8='Accident & Incident Detail'!$I$3:$I$3433)*(Data!AJ4='Accident & Incident Detail'!$C$3:$C$3433))} -> 0 | ... AN8: {=SUM(($A$8='Accident & Incident Detail'!$I$3:$I$3433)*(Data!AN4='Accident & Incident Detail'!$C$3:$C$3433))} -> 0 | AO8: =SUM(AB8:AN8) -> 22
A9: Movement | B9: {=SUM(($A$9='Accident & Incident Detail'!$I$3:$I$3433)*(Data!B4='Accident & Incident Detail'!$C$3:$C$3433))} -> 0 | C9: {=SUM(($A$9='Accident & Incident Detail'!$I$3:$I$3433)*(Data!C4='Accident & Incident Detail'!$C$3:$C$3433))} -> 0 | D9: {=SUM(($A$9='Accident & Incident Detail'!$I$3:$I$3433)*(Data!D4='Accident & Incident Detail'!$C$3:$C$3433))} -> 0 | E9: {=SUM(($A$9='Accident & Incident Detail'!$I$3:$I$3433)*(Data!E4='Accident & Incident Detail'!$C$3:$C$3433))} -> 0 | F9: {=SUM(($A$9='Accident & Incident Detail'!$I$3:$I$3433)*(Data!F4='Accident & Incident Detail'!$C$3:$C$3433))} -> 0 | G9: {=SUM(($A$9='Accident & Incident Detail'!$I$3:$I$3433)*(Data!G4='Accident & Incident Detail'!$C$3:$C$3433))} -> 0 | H9: {=SUM(($A$9='Accident & Incident Detail'!$I$3:$I$3433)*(Data!H4='Accident & Incident Detail'!$C$3:$C$3433))} -> 0 | I9: {=SUM(($A$9='Accident & Incident Detail'!$I$3:$I$3433)*(Data!I4='Accident & Incident Detail'!$C$3:$C$3433))} -> 0 | ... Y9: {=SUM(($A$9='Accident & Incident Detail'!$I$3:$I$3433)*(Data!Y4='Accident & Incident Detail'!$C$3:$C$3433))} -> 4 | Z9: {=SUM(($A$9='Accident & Incident Detail'!$I$3:$I$3433)*(Data!Z8='Accident & Incident Detail'!$C$3:$C$3433))} -> 0 | AA9: {=SUM(($A$9='Accident & Incident Detail'!$I$3:$I$3433)*(Data!AA8='Accident & Incident Detail'!$C$3:$C$3433))} -> 0 | AB9: {=SUM(($A$9='Accident & Incident Detail'!$I$3:$I$3433)*(Data!AB8='Accident & Incident Detail'!$C$3:$C$3433))} -> 0 | AC9: {=SUM(($A$9='Accident & Incident Detail'!$I$3:$I$3433)*(Data!AC4='Accident & Incident Detail'!$C$3:$C$3433))} -> 1 | AD9: {=SUM(($A$9='Accident & Incident Detail'!$I$3:$I$3433)*(Data!AD4='Accident & Incident Detail'!$C$3:$C$3433))} -> 4 | AE9: {=SUM(($A$9='Accident & Incident Detail'!$I$3:$I$3433)*(Data!AE4='Accident & Incident Detail'!$C$3:$C$3433))} -> 6 | AF9: {=SUM(($A$9='Accident & Incident Detail'!$I$3:$I$3433)*(Data!AF4='Accident & Incident Detail'!$C$3:$C$3433))} -> 1 | AG9: {=SUM(($A$9='Accident & Incident Detail'!$I$3:$I$3433)*(Data!AG4='Accident & Incident Detail'!$C$3:$C$3433))} -> 6 | AH9: {=SUM(($A$9='Accident & Incident Detail'!$I$3:$I$3433)*(Data!AH4='Accident & Incident Detail'!$C$3:$C$3433))} -> 5 | AI9: {=SUM(($A$9='Accident & Incident Detail'!$I$3:$I$3433)*(Data!AI4='Accident & Incident Detail'!$C$3:$C$3433))} -> 8 | AJ9: {=SUM(($A$9='Accident & Incident Detail'!$I$3:$I$3433)*(Data!AJ4='Accident & Incident Detail'!$C$3:$C$3433))} -> 9 | ... AN9: {=SUM(($A$9='Accident & Incident Detail'!$I$3:$I$3433)*(Data!AN4='Accident & Incident Detail'!$C$3:$C$3433))} -> 0 | AO9: =SUM(AB9:AN9) -> 46
A10: Non-Movement | B10: {=SUM(($A$10='Accident & Incident Detail'!$I$3:$I$3433)*(Data!B4='Accident & Incident Detail'!$C$3:$C$3433))} -> 0 | C10: {=SUM(($A$10='Accident & Incident Detail'!$I$3:$I$3433)*(Data!C4='Accident & Incident Detail'!$C$3:$C$3433))} -> 0 | D10: {=SUM(($A$10='Accident & Incident Detail'!$I$3:$I$3433)*(Data!D4='Accident & Incident Detail'!$C$3:$C$3433))} -> 0 | E10: {=SUM(($A$10='Accident & Incident Detail'!$I$3:$I$3433)*(Data!E4='Accident & Incident Detail'!$C$3:$C$3433))} -> 0 | F10: {=SUM(($A$10='Accident & Incident Detail'!$I$3:$I$3433)*(Data!F4='Accident & Incident Detail'!$C$3:$C$3433))} -> 0 | G10: {=SUM(($A$10='Accident & Incident Detail'!$I$3:$I$3433)*(Data!G4='Accident & Incident Detail'!$C$3:$C$3433))} -> 0 | H10: {=SUM(($A$10='Accident & Incident Detail'!$I$3:$I$3433)*(Data!H4='Accident & Incident Detail'!$C$3:$C$3433))} -> 0 | I10: {=SUM(($A$10='Accident & Incident Detail'!$I$3:$I$3433)*(Data!I4='Accident & Incident Detail'!$C$3:$C$3433))} -> 0 | ... Y10: {=SUM(($A$10='Accident & Incident Detail'!$I$3:$I$3433)*(Data!Y4='Accident & Incident Detail'!$C$3:$C$3433))} -> 0 | Z10: {=SUM(($A$6='Accident & Incident Detail'!$I$3:$I$3433)*(Data!Z9='Accident & Incident Detail'!$C$3:$C$3433))} -> 0 | AA10: {=SUM(($A$6='Accident & Incident Detail'!$I$3:$I$3433)*(Data!AA9='Accident & Incident Detail'!$C$3:$C$3433))} -> 0 | AB10: {=SUM(($A$10='Accident & Incident Detail'!$I$3:$I$3434)*(Data!AB9='Accident & Incident Detail'!$C$3:$C$3434))} -> 0 | AC10: {=SUM(($A$10='Accident & Incident Detail'!$I$3:$I$3434)*(Data!AC9='Accident & Incident Detail'!$C$3:$C$3434))} -> 0 | AD10: {=SUM(($A$10='Accident & Incident Detail'!$I$3:$I$3434)*(Data!AD9='Accident & Incident Detail'!$C$3:$C$3434))} -> 0 | AE10: {=SUM(($A$10='Accident & Incident Detail'!$I$3:$I$3434)*(Data!AE9='Accident & Incident Detail'!$C$3:$C$3434))} -> 0 | AF10: {=SUM(($A$10='Accident & Incident Detail'!$I$3:$I$3434)*(Data!AF9='Accident & Incident Detail'!$C$3:$C$3434))} -> 0 | AG10: {=SUM(($A$10='Accident & Incident Detail'!$I$3:$I$3434)*(Data!AG9='Accident & Incident Detail'!$C$3:$C$3434))} -> 0 | AH10: {=SUM(($A$10='Accident & Incident Detail'!$I$3:$I$3433)*(Data!AH4='Accident & Incident Detail'!$C$3:$C$3433))} -> 1 | AI10: {=SUM(($A$10='Accident & Incident Detail'!$I$3:$I$3433)*(Data!AI4='Accident & Incident Detail'!$C$3:$C$3433))} -> 0 | AJ10: {=SUM(($A$10='Accident & Incident Detail'!$I$3:$I$3433)*(Data!AJ4='Accident & Incident Detail'!$C$3:$C$3433))} -> 0 | AK10: {=SUM(($A$10='Accident & Incident Detail'!$I$3:$I$3433)*(Data!AK4='Accident & Incident Detail'!$C$3:$C$3433))} -> 0 | AL10: {=SUM(($A$10='Accident & Incident Detail'!$I$3:$I$3433)*(Data!AL4='Accident & Incident Detail'!$C$3:$C$3433))} -> 0 | AM10: {=SUM(($A$10='Accident & Incident Detail'!$I$3:$I$3433)*(Data!AM4='Accident & Incident Detail'!$C$3:$C$3433))} -> 0 | AN10: {=SUM(($A$10='Accident & Incident Detail'!$I$3:$I$3433)*(Data!AN4='Accident & Incident Detail'!$C$3:$C$3433))} -> 0 | AO10: =SUM(AB10:AN10) -> 1
A11: Accidents Total | B11: =SUM(B6:B10) -> 0 | C11: =SUM(C6:C10) -> 0 | D11: =SUM(D6:D10) -> 0 | E11: =SUM(E6:E10) -> 0 | F11: =SUM(F6:F10) -> 0 | G11: =SUM(G6:G10) -> 0 | H11: =SUM(H6:H10) -> 0 | I11: =SUM(I6:I10) -> 0 | ... Y11: =SUM(Y6:Y10) -> 10 | Z11: {=SUM(($A$6='Accident & Incident Detail'!$I$3:$I$3433)*(Data!Z10='Accident & Incident Detail'!$C$3:$C$3433))} -> 0 | AA11: {=SUM(($A$6='Accident & Incident Detail'!$I$3:$I$3433)*(Data!AA10='Accident & Incident Detail'!$C$3:$C$3433))} -> 0 | AB11: =SUM(AB6:AB10) -> 4 | AC11: =SUM(AC6:AC10) -> 6 | AD11: =SUM(AD6:AD10) -> 13 | AE11: =SUM(AE6:AE10) -> 10 | AF11: =SUM(AF6:AF10) -> 2 | AG11: =SUM(AG6:AG10) -> 8 | AH11: =SUM(AH6:AH10) -> 13 | AI11: =SUM(AI6:AI10) -> 9 | ... AN11: =SUM(AN6:AN10) -> 0 | AO11: =SUM(AB11:AN11) -> 93
A12: Vandalism | B12: {=SUM(($A$12='Accident & Incident Detail'!$E$3:$E$3434)*(Data!B4='Accident & Incident Detail'!$C$3:$C$3434))} -> 0 | C12: {=SUM(($A$12='Accident & Incident Detail'!$E$3:$E$3434)*(Data!C4='Accident & Incident Detail'!$C$3:$C$3434))} -> 0 | D12: {=SUM(($A$12='Accident & Incident Detail'!$E$3:$E$3434)*(Data!D4='Accident & Incident Detail'!$C$3:$C$3434))} -> 0 | E12: {=SUM(($A$12='Accident & Incident Detail'!$E$3:$E$3434)*(Data!E4='Accident & Incident Detail'!$C$3:$C$3434))} -> 0 | F12: {=SUM(($A$12='Accident & Incident Detail'!$E$3:$E$3434)*(Data!F4='Accident & Incident Detail'!$C$3:$C$3434))} -> 0 | G12: {=SUM(($A$12='Accident & Incident Detail'!$E$3:$E$3434)*(Data!G4='Accident & Incident Detail'!$C$3:$C$3434))} -> 0 | H12: {=SUM(($A$12='Accident & Incident Detail'!$E$3:$E$3434)*(Data!H4='Accident & Incident Detail'!$C$3:$C$3434))} -> 0 | I12: {=SUM(($A$12='Accident & Incident Detail'!$E$3:$E$3434)*(Data!I4='Accident & Incident Detail'!$C$3:$C$3434))} -> 0 | ... Y12: {=SUM(($A$12='Accident & Incident Detail'!$E$3:$E$3434)*(Data!Y4='Accident & Incident Detail'!$C$3:$C$3434))} -> 3 | Z12: {=SUM(($A$12='Accident & Incident Detail'!$E$3:$E$3433)*(Data!Z4='Accident & Incident Detail'!$C$3:$C$3433))} -> 7 | AA12: {=SUM(($A$12='Accident & Incident Detail'!$E$3:$E$3433)*(Data!AA4='Accident & Incident Detail'!$C$3:$C$3433))} -> 12 | AB12: {=SUM(($A$12='Accident & Incident Detail'!$E$3:$E$3435)*(Data!AB4='Accident & Incident Detail'!$C$3:$C$3435))} -> 11 | AC12: {=SUM(($A$12='Accident & Incident Detail'!$E$3:$E$3435)*(Data!AC4='Accident & Incident Detail'!$C$3:$C$3435))} -> 10 | AD12: {=SUM(($A$12='Accident & Incident Detail'!$E$3:$E$3435)*(Data!AD4='Accident & Incident Detail'!$C$3:$C$3435))} -> 14 | AE12: {=SUM(($A$12='Accident & Incident Detail'!$E$3:$E$3435)*(Data!AE4='Accident & Incident Detail'!$C$3:$C$3435))} -> 5 | AF12: {=SUM(($A$12='Accident & Incident Detail'!$E$3:$E$3435)*(Data!AF4='Accident & Incident Detail'!$C$3:$C$3435))} -> 11 | AG12: {=SUM(($A$12='Accident & Incident Detail'!$E$3:$E$3435)*(Data!AG4='Accident & Incident Detail'!$C$3:$C$3435))} -> 20 | AH12: {=SUM(($A$12='Accident & Incident Detail'!$E$3:$E$3435)*(Data!AH4='Accident & Incident Detail'!$C$3:$C$3435))} -> 16 | AI12: {=SUM(($A$12='Accident & Incident Detail'!$E$3:$E$3435)*(Data!AI4='Accident & Incident Detail'!$C$3:$C$3435))} -> 4 | ... AN12: {=SUM(($A$12='Accident & Incident Detail'!$E$3:$E$3435)*(Data!AN4='Accident & Incident Detail'!$C$3:$C$3435))} -> 0 | AO12: =SUM(AB12:AN12) -> 113
A13: Low Risk Operational | B13: =IF(B1=1,B236,0) -> 0 | C13: =IF(C1=1,C236,0) -> 0 | D13: =IF(D1=1,D236,0) -> 0 | E13: =IF(E1=1,E236,0) -> 0 | F13: =IF(F1=1,F236,0) -> 0 | G13: =IF(G1=1,G236,0) -> 1 | H13: =IF(H1=1,H236,0) -> 1 | I13: =IF(I1=1,I236,0) -> 1 | ... AN13: =IF(AN1=1,AN236,0) -> 0 | AO13: =SUM(AB13:AN13) -> 66
A14: High Risk Operation | B14: =IF(B1=1,B253,0) -> 0 | C14: =IF(C1=1,C253,0) -> 0 | D14: =IF(D1=1,D253,0) -> 0 | E14: =IF(E1=1,E253,0) -> 0 | F14: =IF(F1=1,F253,0) -> 0 | G14: =IF(G1=1,G253,0) -> 0 | H14: =IF(H1=1,H253,0) -> 0 | I14: =IF(I1=1,I253,0) -> 0 | ... AN14: =IF(AN1=1,AN253,0) -> 0 | AO14: =SUM(AB14:AN14) -> 4
A15: Siemens SRD | B15: {=SUM(($A$15='Accident & Incident Detail'!$I$3:$I$3433)*(Data!B4='Accident & Incident Detail'!$C$3:$C$3433))} -> 0 | C15: {=SUM(($A$15='Accident & Incident Detail'!$I$3:$I$3433)*(Data!C4='Accident & Incident Detail'!$C$3:$C$3433))} -> 0 | D15: {=SUM(($A$15='Accident & Incident Detail'!$I$3:$I$3433)*(Data!D4='Accident & Incident Detail'!$C$3:$C$3433))} -> 0 | E15: {=SUM(($A$15='Accident & Incident Detail'!$I$3:$I$3433)*(Data!E4='Accident & Incident Detail'!$C$3:$C$3433))} -> 0 | F15: {=SUM(($A$15='Accident & Incident Detail'!$I$3:$I$3433)*(Data!F4='Accident & Incident Detail'!$C$3:$C$3433))} -> 0 | G15: {=SUM(($A$15='Accident & Incident Detail'!$I$3:$I$3433)*(Data!G4='Accident & Incident Detail'!$C$3:$C$3433))} -> 0 | H15: {=SUM(($A$15='Accident & Incident Detail'!$I$3:$I$3433)*(Data!H4='Accident & Incident Detail'!$C$3:$C$3433))} -> 0 | I15: {=SUM(($A$15='Accident & Incident Detail'!$I$3:$I$3433)*(Data!I4='Accident & Incident Detail'!$C$3:$C$3433))} -> 0 | ... Y15: {=SUM(($A$15='Accident & Incident Detail'!$I$3:$I$3433)*(Data!Y4='Accident & Incident Detail'!$C$3:$C$3433))} -> 0 | Z15: {=SUM(($A$6='Accident & Incident Detail'!$I$3:$I$3433)*(Data!Z14='Accident & Incident Detail'!$C$3:$C$3433))} -> 0 | AA15: {=SUM(($A$6='Accident & Incident Detail'!$I$3:$I$3433)*(Data!AA14='Accident & Incident Detail'!$C$3:$C$3433))} -> 0 | AB15: {=SUM(($A$15='Accident & Incident Detail'!$I$3:$I$3434)*(Data!AB14='Accident & Incident Detail'!$C$3:$C$3434))} -> 0 | AC15: {=SUM(($A$15='Accident & Incident Detail'!$I$3:$I$3434)*(Data!AC4='Accident & Incident Detail'!$C$3:$C$3434))} -> 0 | AD15: {=SUM(($A$15='Accident & Incident Detail'!$I$3:$I$3434)*(Data!AD4='Accident & Incident Detail'!$C$3:$C$3434))} -> 0 | AE15: {=SUM(($A$15='Accident & Incident Detail'!$I$3:$I$3434)*(Data!AE4='Accident & Incident Detail'!$C$3:$C$3434))} -> 1 | AF15: {=SUM(($A$15='Accident & Incident Detail'!$I$3:$I$3434)*(Data!AF4='Accident & Incident Detail'!$C$3:$C$3434))} -> 0 | AG15: {=SUM(($A$15='Accident & Incident Detail'!$I$3:$I$3434)*(Data!AG4='Accident & Incident Detail'!$C$3:$C$3434))} -> 0 | AH15: {=SUM(($A$15='Accident & Incident Detail'!$I$3:$I$3434)*(Data!AH4='Accident & Incident Detail'!$C$3:$C$3434))} -> 0 | AI15: {=SUM(($A$15='Accident & Incident Detail'!$I$3:$I$3434)*(Data!AI4='Accident & Incident Detail'!$C$3:$C$3434))} -> 0 | AJ15: {=SUM(($A$15='Accident & Incident Detail'!$I$3:$I$3434)*(Data!AJ4='Accident & Incident Detail'!$C$3:$C$3434))} -> 0 | ... AN15: {=SUM(($A$15='Accident & Incident Detail'!$I$3:$I$3434)*(Data!AN4='Accident & Incident Detail'!$C$3:$C$3434))} -> 0 | AO15: =SUM(AB15:AN15) -> 1
A16: Citylink SRD | B16: {=SUM(($A$16='Accident & Incident Detail'!$I$3:$I$3433)*(Data!B4='Accident & Incident Detail'!$C$3:$C$3433))} -> 0 | C16: {=SUM(($A$16='Accident & Incident Detail'!$I$3:$I$3433)*(Data!C4='Accident & Incident Detail'!$C$3:$C$3433))} -> 0 | D16: {=SUM(($A$16='Accident & Incident Detail'!$I$3:$I$3433)*(Data!D4='Accident & Incident Detail'!$C$3:$C$3433))} -> 0 | E16: {=SUM(($A$16='Accident & Incident Detail'!$I$3:$I$3433)*(Data!E4='Accident & Incident Detail'!$C$3:$C$3433))} -> 0 | F16: {=SUM(($A$16='Accident & Incident Detail'!$I$3:$I$3433)*(Data!F4='Accident & Incident Detail'!$C$3:$C$3433))} -> 0 | G16: {=SUM(($A$16='Accident & Incident Detail'!$I$3:$I$3433)*(Data!G4='Accident & Incident Detail'!$C$3:$C$3433))} -> 0 | H16: {=SUM(($A$16='Accident & Incident Detail'!$I$3:$I$3433)*(Data!H4='Accident & Incident Detail'!$C$3:$C$3433))} -> 0 | I16: {=SUM(($A$16='Accident & Incident Detail'!$I$3:$I$3433)*(Data!I4='Accident & Incident Detail'!$C$3:$C$3433))} -> 0 | ... Y16: {=SUM(($A$16='Accident & Incident Detail'!$I$3:$I$3433)*(Data!Y4='Accident & Incident Detail'!$C$3:$C$3433))} -> 0 | Z16: {=SUM(($A$6='Accident & Incident Detail'!$I$3:$I$3433)*(Data!Z15='Accident & Incident Detail'!$C$3:$C$3433))} -> 0 | AA16: {=SUM(($A$6='Accident & Incident Detail'!$I$3:$I$3433)*(Data!AA15='Accident & Incident Detail'!$C$3:$C$3433))} -> 0 | AB16: {=SUM(($A$16='Accident & Incident Detail'!$I$3:$I$3434)*(Data!AB15='Accident & Incident Detail'!$C$3:$C$3434))} -> 0 | AC16: {=SUM(($A$16='Accident & Incident Detail'!$I$3:$I$3434)*(Data!AC15='Accident & Incident Detail'!$C$3:$C$3434))} -> 0 | AD16: {=SUM(($A$16='Accident & Incident Detail'!$I$3:$I$3434)*(Data!AD4='Accident & Incident Detail'!$C$3:$C$3434))} -> 0 | AE16: {=SUM(($A$16='Accident & Incident Detail'!$I$3:$I$3434)*(Data!AE15='Accident & Incident Detail'!$C$3:$C$3434))} -> 0 | AF16: {=SUM(($A$16='Accident & Incident Detail'!$I$3:$I$3434)*(Data!AF4='Accident & Incident Detail'!$C$3:$C$3434))} -> 0 | AG16: {=SUM(($A$16='Accident & Incident Detail'!$I$3:$I$3434)*(Data!AG4='Accident & Incident Detail'!$C$3:$C$3434))} -> 0 | AH16: {=SUM(($A$16='Accident & Incident Detail'!$I$3:$I$3434)*(Data!AH4='Accident & Incident Detail'!$C$3:$C$3434))} -> 0 | AI16: {=SUM(($A$16='Accident & Incident Detail'!$I$3:$I$3434)*(Data!AI4='Accident & Incident Detail'!$C$3:$C$3434))} -> 0 | AJ16: {=SUM(($A$16='Accident & Incident Detail'!$I$3:$I$3434)*(Data!AJ4='Accident & Incident Detail'!$C$3:$C$3434))} -> 0 | AK16: {=SUM(($A$16='Accident & Incident Detail'!$I$3:$I$3434)*(Data!AK4='Accident & Incident Detail'!$C$3:$C$3434))} -> 0 | AL16: {=SUM(($A$16='Accident & Incident Detail'!$I$3:$I$3434)*(Data!AL4='Accident & Incident Detail'!$C$3:$C$3434))} -> 0 | AM16: {=SUM(($A$16='Accident & Incident Detail'!$I$3:$I$3434)*(Data!AM4='Accident & Incident Detail'!$C$3:$C$3434))} -> 0 | AN16: {=SUM(($A$16='Accident & Incident Detail'!$I$3:$I$3434)*(Data!AN4='Accident & Incident Detail'!$C$3:$C$3434))} -> 0 | AO16: =SUM(AB16:AN16) -> 0
A17: Incidents Total | B17: =SUM(B12:B15) -> 0 | C17: =SUM(C12:C15) -> 0 | D17: =SUM(D12:D15) -> 0 | E17: =SUM(E12:E15) -> 0 | F17: =SUM(F12:F15) -> 0 | G17: =SUM(G12:G15) -> 1 | H17: =SUM(H12:H15) -> 1 | I17: =SUM(I12:I15) -> 1 | ... AN17: =SUM(AN12:AN15) -> 0 | AO17: =SUM(AB17:AN17) -> 184
A18: Total | B18: =B17+B11 -> 0 | C18: =C17+C11 -> 0 | D18: =D17+D11 -> 0 | E18: =E17+E11 -> 0 | F18: =F17+F11 -> 0 | G18: =G17+G11 -> 1 | H18: =H17+H11 -> 1 | I18: =I17+I11 -> 1 | ... Y18: =Y17+Y11 -> 22 | Z18: {=SUM(($A$6='Accident & Incident Detail'!$I$3:$I$3433)*(Data!Z17='Accident & Incident Detail'!$C$3:$C$3433))} -> 0 | AA18: {=SUM(($A$6='Accident & Incident Detail'!$I$3:$I$3433)*(Data!AA17='Accident & Incident Detail'!$C$3:$C$3433))} -> 0 | AB18: =AB17+AB11 -> 22 | AC18: =AC17+AC11 -> 22 | AD18: =AD17+AD11 -> 33 | AE18: =AE17+AE11 -> 23 | AF18: =AF17+AF11 -> 22 | AG18: =AG17+AG11 -> 32 | AH18: =AH17+AH11 -> 35 | AI18: =AI17+AI11 -> 26 | ... AN18: =AN17+AN11 -> 0 | AO18: =SUM(AB18:AN18) -> 277
A20: MAA
B21: 2301 | C21: 2302 | D21: 2303 | E21: 2304 | F21: 2305 | G21: 2306 | H21: 2307 | I21: 2308 | J21: 2309 | K21: 2310 | L21: 2311 | M21: 2312 | N21: 2313 | O21: 2401 | P21: 2402 | Q21: 2403 | R21: 2404 | S21: 2405 | T21: 2406 | U21: 2407 | V21: 2408 | W21: 2409 | X21: 2410 | Y21: 2411 | Z21: 2412 | AA21: 2413 | AB21: 2501 | AC21: 2502 | AD21: 2503 | AE21: 2504 | AF21: 2505 | AG21: 2506 | AH21: 2507 | AI21: 2508 | AJ21: 2509 | AK21: 2510 | AL21: 2511 | AM21: 2512 | AN21: 2513
A22: Staff Accident | B22: =IF(B$1=1,SUM(SUM(B6:B6)/13),NA()) -> 0 | C22: =IF(C$1=1,SUM(SUM(B6:C6)/13),NA()) -> 0 | D22: =IF(D$1=1,SUM(SUM(B6:D6)/13),NA()) -> 0 | E22: =IF(E$1=1,SUM(SUM(B6:E6)/13),NA()) -> -0.076923077 | F22: =IF(F$1=1,SUM(SUM(B6:F6)/13),NA()) -> -0.076923077 | G22: =IF(G$1=1,SUM(SUM(B6:G6)/13),NA()) -> -0.15384615 | H22: =IF(H$1=1,SUM(SUM(B6:H6)/13),NA()) -> -0.15384615 | I22: =IF(I$1=1,SUM(SUM(B6:I6)/13),NA()) -> -0.15384615 | J22: =IF(J$1=1,SUM(SUM(B6:J6)/13),NA()) -> -0.076923077 | K22: =IF(K$1=1,SUM(SUM(B6:K6)/13),NA()) -> 0.076923077 | L22: =IF(L$1=1,SUM(SUM(B6:L6)/13),NA()) -> 0.30769231 | M22: =IF(M$1=1,SUM(SUM(B6:M6)/13),NA()) -> 0.38461538 | N22: =IF(N$1=1,SUM(SUM(B6:N6)/13),NA()) -> 0.38461538 | O22: =IF(O$1=1,SUM(SUM(C6:O6)/13),NA()) -> 0.46153846 | P22: =IF(P$1=1,SUM(SUM(D6:P6)/13),NA()) -> 0.69230769 | Q22: =IF(Q$1=1,SUM(SUM(E6:Q6)/13),NA()) -> 0.69230769 | R22: =IF(R$1=1,SUM(SUM(F6:R6)/13),NA()) -> 0.92307692 | S22: =IF(S$1=1,SUM(SUM(G6:S6)/13),NA()) -> 1.0769231 | T22: =IF(T$1=1,SUM(SUM(H6:T6)/13),NA()) -> 1.2307692 | U22: =IF(U$1=1,SUM(SUM(I6:U6)/13),NA()) -> 1.4615385 | ... AN22: =IF(AN$1=1,SUM(SUM(AB6:AN6)/13),NA()) -> #N/A | AO22: =SUM(AC22:AN22) -> #N/A
A23: Staff LTA | B23: =IF(B$1=1,SUM(SUM(B7:B7)/13),NA()) -> 0 | C23: =IF(C$1=1,SUM(SUM(B7:C7)/13),NA()) -> 0 | D23: =IF(D$1=1,SUM(SUM(B7:D7)/13),NA()) -> 0 | E23: =IF(E$1=1,SUM(SUM(B7:E7)/13),NA()) -> 0.076923077 | F23: =IF(F$1=1,SUM(SUM(B7:F7)/13),NA()) -> 0.076923077 | G23: =IF(G$1=1,SUM(SUM(B7:G7)/13),NA()) -> 0.15384615 | H23: =IF(H$1=1,SUM(SUM(B7:H7)/13),NA()) -> 0.15384615 | I23: =IF(I$1=1,SUM(SUM(B7:I7)/13),NA()) -> 0.15384615 | J23: =IF(J$1=1,SUM(SUM(B7:J7)/13),NA()) -> 0.15384615 | K23: =IF(K$1=1,SUM(SUM(B7:K7)/13),NA()) -> 0.15384615 | L23: =IF(L$1=1,SUM(SUM(B7:L7)/13),NA()) -> 0.15384615 | M23: =IF(M$1=1,SUM(SUM(B7:M7)/13),NA()) -> 0.15384615 | N23: =IF(N$1=1,SUM(SUM(B7:N7)/13),NA()) -> 0.15384615 | O23: =IF(O$1=1,SUM(SUM(C7:O7)/13),NA()) -> 0.15384615 | P23: =IF(P$1=1,SUM(SUM(D7:P7)/13),NA()) -> 0.23076923 | Q23: =IF(Q$1=1,SUM(SUM(E7:Q7)/13),NA()) -> 0.23076923 | R23: =IF(R$1=1,SUM(SUM(F7:R7)/13),NA()) -> 0.15384615 | S23: =IF(S$1=1,SUM(SUM(G7:S7)/13),NA()) -> 0.15384615 | T23: =IF(T$1=1,SUM(SUM(H7:T7)/13),NA()) -> 0.076923077 | U23: =IF(U$1=1,SUM(SUM(I7:U7)/13),NA()) -> 0.076923077 | ... AN23: =IF(AN$1=1,SUM(SUM(AB7:AN7)/13),NA()) -> #N/A | AO23: =SUM(AC23:AN23) -> #N/A
A24: Assaults | B24: =IF(B$1=1,SUM(SUM(B8:B8)/13),NA()) -> 0 | C24: =IF(C$1=1,SUM(SUM(B8:C8)/13),NA()) -> 0 | D24: =IF(D$1=1,SUM(SUM(B8:D8)/13),NA()) -> 0 | E24: =IF(E$1=1,SUM(SUM(B8:E8)/13),NA()) -> 0 | F24: =IF(F$1=1,SUM(SUM(B8:F8)/13),NA()) -> 0 | G24: =IF(G$1=1,SUM(SUM(B8:G8)/13),NA()) -> 0 | H24: =IF(H$1=1,SUM(SUM(B8:H8)/13),NA()) -> 0 | I24: =IF(I$1=1,SUM(SUM(B8:I8)/13),NA()) -> 0 | J24: =IF(J$1=1,SUM(SUM(B8:J8)/13),NA()) -> 0.15384615 | K24: =IF(K$1=1,SUM(SUM(B8:K8)/13),NA()) -> 0.53846154 | L24: =IF(L$1=1,SUM(SUM(B8:L8)/13),NA()) -> 0.76923077 | M24: =IF(M$1=1,SUM(SUM(B8:M8)/13),NA()) -> 1.2307692 | N24: =IF(N$1=1,SUM(SUM(B8:N8)/13),NA()) -> 1.2307692 | O24: =IF(O$1=1,SUM(SUM(C8:O8)/13),NA()) -> 1.9230769 | P24: =IF(P$1=1,SUM(SUM(D8:P8)/13),NA()) -> 2.2307692 | Q24: =IF(Q$1=1,SUM(SUM(E8:Q8)/13),NA()) -> 2.5384615 | R24: =IF(R$1=1,SUM(SUM(F8:R8)/13),NA()) -> 2.8461538 | S24: =IF(S$1=1,SUM(SUM(G8:S8)/13),NA()) -> 3.0769231 | T24: =IF(T$1=1,SUM(SUM(H8:T8)/13),NA()) -> 3.3846154 | U24: =IF(U$1=1,SUM(SUM(I8:U8)/13),NA()) -> 3.8461538 | ... AN24: =IF(AN$1=1,SUM(SUM(AB8:AN8)/13),NA()) -> #N/A | AO24: =SUM(AC24:AN24) -> #N/A
A25: Movement | B25: =IF(B$1=1,(SUM(SUM(B9:B9))/13),NA()) -> 0 | C25: =IF(C$1=1,(SUM(SUM(B9:C9))/13),NA()) -> 0 | D25: =IF(D$1=1,(SUM(SUM(B9:D9))/13),NA()) -> 0 | E25: =IF(E$1=1,(SUM(SUM(B9:E9))/13),NA()) -> 0 | F25: =IF(F$1=1,(SUM(SUM(B9:F9))/13),NA()) -> 0 | G25: =IF(G$1=1,(SUM(SUM(B9:G9))/13),NA()) -> 0 | H25: =IF(H$1=1,(SUM(SUM(B9:H9))/13),NA()) -> 0 | I25: =IF(I$1=1,(SUM(SUM(B9:I9))/13),NA()) -> 0 | J25: =IF(J$1=1,(SUM(SUM(B9:J9))/13),NA()) -> 0.076923077 | K25: =IF(K$1=1,(SUM(SUM(B9:K9))/13),NA()) -> 0.30769231 | L25: =IF(L$1=1,(SUM(SUM(B9:L9))/13),NA()) -> 0.84615385 | M25: =IF(M$1=1,(SUM(SUM(B9:M9))/13),NA()) -> 1.3846154 | N25: =IF(N$1=1,(SUM(SUM(B9:N9))/13),NA()) -> 1.3846154 | O25: =IF(O$1=1,(SUM(SUM(C9:O9))/13),NA()) -> 2.0769231 | P25: =IF(P$1=1,(SUM(SUM(D9:P9))/13),NA()) -> 2.5384615 | Q25: =IF(Q$1=1,(SUM(SUM(E9:Q9))/13),NA()) -> 3.2307692 | R25: =IF(R$1=1,(SUM(SUM(F9:R9))/13),NA()) -> 3.6923077 | S25: =IF(S$1=1,(SUM(SUM(G9:S9))/13),NA()) -> 3.9230769 | T25: =IF(T$1=1,(SUM(SUM(H9:T9))/13),NA()) -> 4.4615385 | U25: =IF(U$1=1,(SUM(SUM(I9:U9))/13),NA()) -> 5 | ... AN25: =IF(AN$1=1,(SUM(SUM(AB9:AN9))/13),NA()) -> #N/A | AO25: =SUM(AC25:AN25) -> #N/A
A26: Movement (Old) | B26: 91.615385 | C26: 92.615385 | D26: 93.615385 | E26: 94.615385 | F26: 95.615385 | G26: 96.615385 | H26: 97.615385 | I26: 98.615385 | J26: 99.615385 | K26: 100.61538 | L26: 101.61538 | M26: 102.61538 | N26: 103.61538 | O26: 104.61538 | P26: 105.61538 | Q26: 106.61538 | R26: 107.61538 | S26: 108.61538 | T26: 109.61538 | U26: 110.61538 | V26: 111.61538 | W26: 112.61538 | X26: 113.61538 | Y26: 114.61538 | Z26: 115.61538 | AA26: 116.61538 | AB26: 117.61538 | AC26: 118.61538 | AD26: 119.61538 | AE26: 120.61538 | AF26: 121.61538 | AG26: 122.61538 | AH26: 123.61538 | AI26: 124.61538 | AJ26: 125.61538 | AK26: 126.61538 | AL26: 127.61538 | AM26: 128.61538 | AN26: 129.61538 | AO26: =SUM(AC26:AN26) -> 1489.3846
A27: Non-Movement MAA | B27: =IF(B$1=1,(SUM(SUM(B10:B10))/13),NA()) -> 0 | C27: =IF(C$1=1,(SUM(SUM(B10:C10))/13),NA()) -> 0 | D27: =IF(D$1=1,(SUM(SUM(B10:D10))/13),NA()) -> 0 | E27: =IF(E$1=1,(SUM(SUM(B10:E10))/13),NA()) -> 0 | F27: =IF(F$1=1,(SUM(SUM(B10:F10))/13),NA()) -> 0 | G27: =IF(G$1=1,(SUM(SUM(B10:G10))/13),NA()) -> 0 | H27: =IF(H$1=1,(SUM(SUM(B10:H10))/13),NA()) -> 0 | I27: =IF(I$1=1,(SUM(SUM(B10:I10))/13),NA()) -> 0 | J27: =IF(J$1=1,(SUM(SUM(B10:J10))/13),NA()) -> 0 | K27: =IF(K$1=1,(SUM(SUM(B10:K10))/13),NA()) -> 0 | L27: =IF(L$1=1,(SUM(SUM(B10:L10))/13),NA()) -> 0 | M27: =IF(M$1=1,(SUM(SUM(B10:M10))/13),NA()) -> 0.076923077 | N27: =IF(N$1=1,(SUM(SUM(B10:N10))/13),NA()) -> 0.076923077 | O27: =IF(O$1=1,(SUM(SUM(C10:O10))/13),NA()) -> 0.15384615 | P27: =IF(P$1=1,(SUM(SUM(D10:P10))/13),NA()) -> 0.23076923 | Q27: =IF(Q$1=1,(SUM(SUM(E10:Q10))/13),NA()) -> 0.23076923 | R27: =IF(R$1=1,(SUM(SUM(F10:R10))/13),NA()) -> 0.38461538 | S27: =IF(S$1=1,(SUM(SUM(G10:S10))/13),NA()) -> 0.38461538 | T27: =IF(T$1=1,(SUM(SUM(H10:T10))/13),NA()) -> 0.38461538 | U27: =IF(U$1=1,(SUM(SUM(I10:U10))/13),NA()) -> 0.46153846 | ... AN27: =IF(AN$1=1,(SUM(SUM(AB10:AN10))/13),NA()) -> #N/A | AO27: =SUM(AC27:AN27) -> #N/A
A28: Non-Movement (Old) | B28: #N/A | C28: #N/A | D28: #N/A | E28: #N/A | F28: #N/A | G28: #N/A | H28: #N/A | I28: #N/A | J28: #N/A | K28: #N/A | L28: #N/A | M28: #N/A | N28: #N/A | O28: #N/A | P28: #N/A | Q28: #N/A | R28: #N/A | S28: #N/A | T28: #N/A | U28: #N/A | V28: #N/A | W28: #N/A | X28: #N/A | Y28: #N/A | Z28: #N/A | AA28: #N/A | AB28: #N/A | AC28: #N/A | AD28: #N/A | AE28: #N/A | AF28: #N/A | AG28: #N/A | AH28: #N/A | AI28: #N/A | AJ28: #N/A | AK28: #N/A | AL28: #N/A | AM28: #N/A | AN28: #N/A | AO28: =SUM(AC28:AN28) -> #N/A
A29: Accidents Total | B29: =IF(B$1=1,SUM(SUM(B11:B11)/13),NA()) -> 0 | C29: =IF(C$1=1,SUM(SUM(B11:C11)/13),NA()) -> 0 | D29: =IF(D$1=1,SUM(SUM(B11:D11)/13),NA()) -> 0 | E29: =IF(E$1=1,SUM(SUM(B11:E11)/13),NA()) -> 0 | F29: =IF(F$1=1,SUM(SUM(B11:F11)/13),NA()) -> 0 | G29: =IF(G$1=1,SUM(SUM(B11:G11)/13),NA()) -> 0 | H29: =IF(H$1=1,SUM(SUM(B11:H11)/13),NA()) -> 0 | I29: =IF(I$1=1,SUM(SUM(B11:I11)/13),NA()) -> 0 | J29: =IF(J$1=1,SUM(SUM(B11:J11)/13),NA()) -> 0.30769231 | K29: =IF(K$1=1,SUM(SUM(B11:K11)/13),NA()) -> 1.0769231 | L29: =IF(L$1=1,SUM(SUM(B11:L11)/13),NA()) -> 2.0769231 | M29: =IF(M$1=1,SUM(SUM(B11:M11)/13),NA()) -> 3.2307692 | N29: =IF(N$1=1,SUM(SUM(B11:N11)/13),NA()) -> 3.2307692 | O29: =IF(O$1=1,SUM(SUM(C11:O11)/13),NA()) -> 4.7692308 | P29: =IF(P$1=1,SUM(SUM(D11:P11)/13),NA()) -> 5.9230769 | Q29: =IF(Q$1=1,SUM(SUM(E11:Q11)/13),NA()) -> 6.9230769 | R29: =IF(R$1=1,SUM(SUM(F11:R11)/13),NA()) -> 8 | S29: =IF(S$1=1,SUM(SUM(G11:S11)/13),NA()) -> 8.6153846 | T29: =IF(T$1=1,SUM(SUM(H11:T11)/13),NA()) -> 9.5384615 | U29: =IF(U$1=1,SUM(SUM(I11:U11)/13),NA()) -> 10.846154 | ... AN29: =IF(AN$1=1,SUM(SUM(AB11:AN11)/13),NA()) -> #N/A | AO29: =SUM(AC29:AN29) -> #N/A
A30: Vandalism | B30: =IF(B$1=1,SUM(SUM(B12:B12)/13),NA()) -> 0 | C30: =IF(C$1=1,SUM(SUM(B12:C12)/13),NA()) -> 0 | D30: =IF(D$1=1,SUM(SUM(B12:D12)/13),NA()) -> 0 | E30: =IF(E$1=1,SUM(SUM(B12:E12)/13),NA()) -> 0 | F30: =IF(F$1=1,SUM(SUM(B12:F12)/13),NA()) -> 0 | G30: =IF(G$1=1,SUM(SUM(B12:G12)/13),NA()) -> 0 | H30: =IF(H$1=1,SUM(SUM(B12:H12)/13),NA()) -> 0 | I30: =IF(I$1=1,SUM(SUM(B12:I12)/13),NA()) -> 0 | J30: =IF(J$1=1,SUM(SUM(B12:J12)/13),NA()) -> 0.076923077 | K30: =IF(K$1=1,SUM(SUM(B12:K12)/13),NA()) -> 0.76923077 | L30: =IF(L$1=1,SUM(SUM(B12:L12)/13),NA()) -> 1.0769231 | M30: =IF(M$1=1,SUM(SUM(B12:M12)/13),NA()) -> 1.5384615 | N30: =IF(N$1=1,SUM(SUM(B12:N12)/13),NA()) -> 1.5384615 | O30: =IF(O$1=1,SUM(SUM(C12:O12)/13),NA()) -> 2.0769231 | P30: =IF(P$1=1,SUM(SUM(D12:P12)/13),NA()) -> 2.3846154 | Q30: =IF(Q$1=1,SUM(SUM(E12:Q12)/13),NA()) -> 2.9230769 | R30: =IF(R$1=1,SUM(SUM(F12:R12)/13),NA()) -> 3.3076923 | S30: =IF(S$1=1,SUM(SUM(G12:S12)/13),NA()) -> 3.5384615 | T30: =IF(T$1=1,SUM(SUM(H12:T12)/13),NA()) -> 3.9230769 | U30: =IF(U$1=1,SUM(SUM(I12:U12)/13),NA()) -> 4.3846154 | ... AN30: =IF(AN$1=1,SUM(SUM(AB12:AN12)/13),NA()) -> #N/A | AO30: =SUM(AC30:AN30) -> #N/A
A31: Low Risk Operational | B31: =IF(B$1=1,SUM(SUM(B13:B13)/13),NA()) -> 0 | C31: =IF(C$1=1,SUM(SUM(B13:C13)/13),NA()) -> 0 | D31: =IF(D$1=1,SUM(SUM(B13:D13)/13),NA()) -> 0 | E31: =IF(E$1=1,SUM(SUM(B13:E13)/13),NA()) -> 0 | F31: =IF(F$1=1,SUM(SUM(B13:F13)/13),NA()) -> 0 | G31: =IF(G$1=1,SUM(SUM(B13:G13)/13),NA()) -> 0.076923077 | H31: =IF(H$1=1,SUM(SUM(B13:H13)/13),NA()) -> 0.15384615 | I31: =IF(I$1=1,SUM(SUM(B13:I13)/13),NA()) -> 0.23076923 | J31: =IF(J$1=1,SUM(SUM(B13:J13)/13),NA()) -> 0.46153846 | K31: =IF(K$1=1,SUM(SUM(B13:K13)/13),NA()) -> 1.1538462 | L31: =IF(L$1=1,SUM(SUM(B13:L13)/13),NA()) -> 2 | M31: =IF(M$1=1,SUM(SUM(B13:M13)/13),NA()) -> 2.4615385 | N31: =IF(N$1=1,SUM(SUM(B13:N13)/13),NA()) -> 2.4615385 | O31: =IF(O$1=1,SUM(SUM(C13:O13)/13),NA()) -> 3 | P31: =IF(P$1=1,SUM(SUM(D13:P13)/13),NA()) -> 3.4615385 | Q31: =IF(Q$1=1,SUM(SUM(E13:Q13)/13),NA()) -> 4.0769231 | R31: =IF(R$1=1,SUM(SUM(F13:R13)/13),NA()) -> 4.7692308 | S31: =IF(S$1=1,SUM(SUM(G13:S13)/13),NA()) -> 5.0769231 | T31: =IF(T$1=1,SUM(SUM(H13:T13)/13),NA()) -> 5.3076923 | U31: =IF(U$1=1,SUM(SUM(I13:U13)/13),NA()) -> 5.6153846 | ... AN31: =IF(AN$1=1,SUM(SUM(AB13:AN13)/13),NA()) -> #N/A | AO31: =SUM(AC31:AN31) -> #N/A
A32: High Risk Operational | B32: =IF(B$1=1,SUM(SUM(B14:B14)/13),NA()) -> 0 | C32: =IF(C$1=1,SUM(SUM(B14:C14)/13),NA()) -> 0 | D32: =IF(D$1=1,SUM(SUM(B14:D14)/13),NA()) -> 0 | E32: =IF(E$1=1,SUM(SUM(B14:E14)/13),NA()) -> 0 | F32: =IF(F$1=1,SUM(SUM(B14:F14)/13),NA()) -> 0 | G32: =IF(G$1=1,SUM(SUM(B14:G14)/13),NA()) -> 0 | H32: =IF(H$1=1,SUM(SUM(B14:H14)/13),NA()) -> 0 | I32: =IF(I$1=1,SUM(SUM(B14:I14)/13),NA()) -> 0 | J32: =IF(J$1=1,SUM(SUM(B14:J14)/13),NA()) -> 0.076923077 | K32: =IF(K$1=1,SUM(SUM(B14:K14)/13),NA()) -> 0.076923077 | L32: =IF(L$1=1,SUM(SUM(B14:L14)/13),NA()) -> 0.076923077 | M32: =IF(M$1=1,SUM(SUM(B14:M14)/13),NA()) -> 0.076923077 | N32: =IF(N$1=1,SUM(SUM(B14:N14)/13),NA()) -> 0.076923077 | O32: =IF(O$1=1,SUM(SUM(C14:O14)/13),NA()) -> 0.15384615 | P32: =IF(P$1=1,SUM(SUM(D14:P14)/13),NA()) -> 0.38461538 | Q32: =IF(Q$1=1,SUM(SUM(E14:Q14)/13),NA()) -> 0.38461538 | R32: =IF(R$1=1,SUM(SUM(F14:R14)/13),NA()) -> 0.38461538 | S32: =IF(S$1=1,SUM(SUM(G14:S14)/13),NA()) -> 0.38461538 | T32: =IF(T$1=1,SUM(SUM(H14:T14)/13),NA()) -> 0.46153846 | U32: =IF(U$1=1,SUM(SUM(I14:U14)/13),NA()) -> 0.46153846 | ... AN32: =IF(AN$1=1,SUM(SUM(AB14:AN14)/13),NA()) -> #N/A | AO32: =SUM(AC32:AN32) -> #N/A
A33: SRD | B33: =IF(B$1=1,SUM(SUM(B15:B15)/13),NA()) -> 0 | C33: =IF(C$1=1,SUM(SUM(B15:C15)/13),NA()) -> 0 | D33: =IF(D$1=1,SUM(SUM(B15:D15)/13),NA()) -> 0 | E33: =IF(E$1=1,SUM(SUM(B15:E15)/13),NA()) -> 0 | F33: =IF(F$1=1,SUM(SUM(B15:F15)/13),NA()) -> 0 | G33: =IF(G$1=1,SUM(SUM(B15:G15)/13),NA()) -> 0 | H33: =IF(H$1=1,SUM(SUM(B15:H15)/13),NA()) -> 0 | I33: =IF(I$1=1,SUM(SUM(B15:I15)/13),NA()) -> 0 | J33: =IF(J$1=1,SUM(SUM(B15:J15)/13),NA()) -> 0 | K33: =IF(K$1=1,SUM(SUM(B15:K15)/13),NA()) -> 0 | L33: =IF(L$1=1,SUM(SUM(B15:L15)/13),NA()) -> 0 | M33: =IF(M$1=1,SUM(SUM(B15:M15)/13),NA()) -> 0.076923077 | N33: =IF(N$1=1,SUM(SUM(B15:N15)/13),NA()) -> 0.076923077 | O33: =IF(O$1=1,SUM(SUM(C15:O15)/13),NA()) -> 0.15384615 | P33: =IF(P$1=1,SUM(SUM(D15:P15)/13),NA()) -> 0.15384615 | Q33: =IF(Q$1=1,SUM(SUM(E15:Q15)/13),NA()) -> 0.15384615 | R33: =IF(R$1=1,SUM(SUM(F15:R15)/13),NA()) -> 0.15384615 | S33: =IF(S$1=1,SUM(SUM(G15:S15)/13),NA()) -> 0.15384615 | T33: =IF(T$1=1,SUM(SUM(H15:T15)/13),NA()) -> 0.15384615 | U33: =IF(U$1=1,SUM(SUM(I15:U15)/13),NA()) -> 0.15384615 | ... AN33: =IF(AN$1=1,SUM(SUM(AB15:AN15)/13),NA()) -> #N/A | AO33: =SUM(AC33:AN33) -> #N/A
A34: Incidents Total | B34: =IF(B$1=1,SUM(SUM(B17:B17)/13),NA()) -> 0 | C34: =IF(C$1=1,SUM(SUM(B17:C17)/13),NA()) -> 0 | D34: =IF(D$1=1,SUM(SUM(B17:D17)/13),NA()) -> 0 | E34: =IF(E$1=1,SUM(SUM(B17:E17)/13),NA()) -> 0 | F34: =IF(F$1=1,SUM(SUM(B17:F17)/13),NA()) -> 0 | G34: =IF(G$1=1,SUM(SUM(B17:G17)/13),NA()) -> 0.076923077 | H34: =IF(H$1=1,SUM(SUM(B17:H17)/13),NA()) -> 0.15384615 | I34: =IF(I$1=1,SUM(SUM(B17:I17)/13),NA()) -> 0.23076923 | J34: =IF(J$1=1,SUM(SUM(B17:J17)/13),NA()) -> 0.61538462 | K34: =IF(K$1=1,SUM(SUM(B17:K17)/13),NA()) -> 2 | L34: =IF(L$1=1,SUM(SUM(B17:L17)/13),NA()) -> 3.1538462 | M34: =IF(M$1=1,SUM(SUM(B17:M17)/13),NA()) -> 4.1538462 | N34: =IF(N$1=1,SUM(SUM(B17:N17)/13),NA()) -> 4.1538462 | O34: =IF(O$1=1,SUM(SUM(C17:O17)/13),NA()) -> 5.3846154 | P34: =IF(P$1=1,SUM(SUM(D17:P17)/13),NA()) -> 6.3846154 | Q34: =IF(Q$1=1,SUM(SUM(E17:Q17)/13),NA()) -> 7.5384615 | R34: =IF(R$1=1,SUM(SUM(F17:R17)/13),NA()) -> 8.6153846 | S34: =IF(S$1=1,SUM(SUM(G17:S17)/13),NA()) -> 9.1538462 | T34: =IF(T$1=1,SUM(SUM(H17:T17)/13),NA()) -> 9.8461538 | U34: =IF(U$1=1,SUM(SUM(I17:U17)/13),NA()) -> 10.615385 | ... AN34: =IF(AN$1=1,SUM(SUM(AB17:AN17)/13),NA()) -> #N/A | AO34: =SUM(AC34:AN34) -> #N/A
A35: Total | B35: =IF(B$1=1,SUM(SUM(B18:B18)/13),NA()) -> 0 | C35: =IF(C$1=1,SUM(SUM(B18:C18)/13),NA()) -> 0 | D35: =IF(D$1=1,SUM(SUM(B18:D18)/13),NA()) -> 0 | E35: =IF(E$1=1,SUM(SUM(B18:E18)/13),NA()) -> 0 | F35: =IF(F$1=1,SUM(SUM(B18:F18)/13),NA()) -> 0 | G35: =IF(G$1=1,SUM(SUM(B18:G18)/13),NA()) -> 0.076923077 | H35: =IF(H$1=1,SUM(SUM(B18:H18)/13),NA()) -> 0.15384615 | I35: =IF(I$1=1,SUM(SUM(B18:I18)/13),NA()) -> 0.23076923 | J35: =IF(J$1=1,SUM(SUM(B18:J18)/13),NA()) -> 0.92307692 | K35: =IF(K$1=1,SUM(SUM(B18:K18)/13),NA()) -> 3.0769231 | L35: =IF(L$1=1,SUM(SUM(B18:L18)/13),NA()) -> 5.2307692 | M35: =IF(M$1=1,SUM(SUM(B18:M18)/13),NA()) -> 7.3846154 | N35: =IF(N$1=1,SUM(SUM(B18:N18)/13),NA()) -> 7.3846154 | O35: =IF(O$1=1,SUM(SUM(C18:O18)/13),NA()) -> 10.153846 | P35: =IF(P$1=1,SUM(SUM(D18:P18)/13),NA()) -> 12.307692 | Q35: =IF(Q$1=1,SUM(SUM(E18:Q18)/13),NA()) -> 14.461538 | R35: =IF(R$1=1,SUM(SUM(F18:R18)/13),NA()) -> 16.615385 | S35: =IF(S$1=1,SUM(SUM(G18:S18)/13),NA()) -> 17.769231 | T35: =IF(T$1=1,SUM(SUM(H18:T18)/13),NA()) -> 19.384615 | U35: =IF(U$1=1,SUM(SUM(I18:U18)/13),NA()) -> 21.461538 | ... AN35: =IF(AN$1=1,SUM(SUM(AB18:AN18)/13),NA()) -> #N/A | AO35: =SUM(AC35:AN35) -> #N/A
A37: All Staff Accident
A38: Staff Accident | B38: 2301 | C38: 2302 | D38: 2303 | E38: 2304 | F38: 2305 | G38: 2306 | H38: 2307 | I38: 2308 | J38: 2309 | K38: 2310 | L38: 2311 | M38: 2312 | N38: 2313 | O38: 2401 | P38: 2402 | Q38: 2403 | R38: 2404 | S38: 2405 | T38: 2406 | U38: 2407 | V38: 2408 | W38: 2409 | X38: 2410 | Y38: 2411 | Z38: 2412 | AA38: 2413 | AB38: 2501 | AC38: 2502 | AD38: 2503 | AE38: 2504 | AF38: 2505 | AG38: 2506 | AH38: 2507 | AI38: 2508 | AJ38: 2509 | AK38: 2510 | AL38: 2511 | AM38: 2512 | AN38: 2513
A39: Burn/Scald | B39: {=SUM((B38='Accident & Incident Detail'!$C$2:$C$3433)*($A$38='Accident & Incident Detail'!$I$2:$I$3433)*($A$39='Accident & Incident Detail'!$E$2:$E$3433))} -> 0 | C39: {=SUM((C38='Accident & Incident Detail'!$C$2:$C$3433)*($A$38='Accident & Incident Detail'!$I$2:$I$3433)*($A$39='Accident & Incident Detail'!$E$2:$E$3433))} -> 0 | D39: {=SUM((D38='Accident & Incident Detail'!$C$2:$C$3433)*($A$38='Accident & Incident Detail'!$I$2:$I$3433)*($A$39='Accident & Incident Detail'!$E$2:$E$3433))} -> 0 | E39: {=SUM((E38='Accident & Incident Detail'!$C$2:$C$3433)*($A$38='Accident & Incident Detail'!$I$2:$I$3433)*($A$39='Accident & Incident Detail'!$E$2:$E$3433))} -> 0 | F39: {=SUM((F38='Accident & Incident Detail'!$C$2:$C$3433)*($A$38='Accident & Incident Detail'!$I$2:$I$3433)*($A$39='Accident & Incident Detail'!$E$2:$E$3433))} -> 0 | G39: {=SUM((G38='Accident & Incident Detail'!$C$2:$C$3433)*($A$38='Accident & Incident Detail'!$I$2:$I$3433)*($A$39='Accident & Incident Detail'!$E$2:$E$3433))} -> 0 | H39: {=SUM((H38='Accident & Incident Detail'!$C$2:$C$3433)*($A$38='Accident & Incident Detail'!$I$2:$I$3433)*($A$39='Accident & Incident Detail'!$E$2:$E$3433))} -> 0 | I39: {=SUM((I38='Accident & Incident Detail'!$C$2:$C$3433)*($A$38='Accident & Incident Detail'!$I$2:$I$3433)*($A$39='Accident & Incident Detail'!$E$2:$E$3433))} -> 0 | ... AN39: {=SUM((AN38='Accident & Incident Detail'!$C$2:$C$3433)*($A$38='Accident & Incident Detail'!$I$2:$I$3433)*($A$39='Accident & Incident Detail'!$E$2:$E$3433))} -> 0
A40: MAA | B40: =IF(B$1=1,(SUM(B39:B39)/13),0) -> 0 | C40: =IF(C$1=1,(SUM(B39:C39)/13),0) -> 0 | D40: =IF(D$1=1,(SUM(B39:D39)/13),0) -> 0 | E40: =IF(E$1=1,(SUM(B39:E39)/13),0) -> 0 | F40: =IF(F$1=1,(SUM(B39:F39)/13),0) -> 0 | G40: =IF(G$1=1,(SUM(B39:G39)/13),0) -> 0 | H40: =IF(H$1=1,(SUM(B39:H39)/13),0) -> 0 | I40: =IF(I$1=1,(SUM(B39:I39)/13),0) -> 0 | J40: =IF(J$1=1,(SUM(B39:J39)/13),0) -> 0 | K40: =IF(K$1=1,(SUM(B39:K39)/13),0) -> 0 | L40: =IF(L$1=1,(SUM(B39:L39)/13),0) -> 0 | M40: =IF(M$1=1,(SUM(B39:M39)/13),0) -> 0 | N40: =IF(N$1=1,(SUM(B39:N39)/13),0) -> 0 | O40: =IF(O$1=1,(SUM(C39:O39)/13),0) -> 0 | P40: =IF(P$1=1,(SUM(D39:P39)/13),0) -> 0 | Q40: =IF(Q$1=1,(SUM(E39:Q39)/13),0) -> 0 | R40: =IF(R$1=1,(SUM(F39:R39)/13),0) -> 0 | S40: =IF(S$1=1,(SUM(G39:S39)/13),0) -> 0 | T40: =IF(T$1=1,(SUM(H39:T39)/13),0) -> 0 | U40: =IF(U$1=1,(SUM(I39:U39)/13),0) -> 0 | ... AN40: =IF(AN$1=1,(SUM(AB39:AN39)/13),0) -> 0
A41: Contact | B41: {=SUM((B38='Accident & Incident Detail'!$C$2:$C$3433)*($A$38='Accident & Incident Detail'!$I$2:$I$3433)*($A$41='Accident & Incident Detail'!$E$2:$E$3433))} -> 0 | C41: {=SUM((C38='Accident & Incident Detail'!$C$2:$C$3433)*($A$38='Accident & Incident Detail'!$I$2:$I$3433)*($A$41='Accident & Incident Detail'!$E$2:$E$3433))} -> 0 | D41: {=SUM((D38='Accident & Incident Detail'!$C$2:$C$3433)*($A$38='Accident & Incident Detail'!$I$2:$I$3433)*($A$41='Accident & Incident Detail'!$E$2:$E$3433))} -> 0 | E41: {=SUM((E38='Accident & Incident Detail'!$C$2:$C$3433)*($A$38='Accident & Incident Detail'!$I$2:$I$3433)*($A$41='Accident & Incident Detail'!$E$2:$E$3433))} -> 0 | F41: {=SUM((F38='Accident & Incident Detail'!$C$2:$C$3433)*($A$38='Accident & Incident Detail'!$I$2:$I$3433)*($A$41='Accident & Incident Detail'!$E$2:$E$3433))} -> 0 | G41: {=SUM((G38='Accident & Incident Detail'!$C$2:$C$3433)*($A$38='Accident & Incident Detail'!$I$2:$I$3433)*($A$41='Accident & Incident Detail'!$E$2:$E$3433))} -> 0 | H41: {=SUM((H38='Accident & Incident Detail'!$C$2:$C$3433)*($A$38='Accident & Incident Detail'!$I$2:$I$3433)*($A$41='Accident & Incident Detail'!$E$2:$E$3433))} -> 0 | I41: {=SUM((I38='Accident & Incident Detail'!$C$2:$C$3433)*($A$38='Accident & Incident Detail'!$I$2:$I$3433)*($A$41='Accident & Incident Detail'!$E$2:$E$3433))} -> 0 | ... AN41: {=SUM((AN38='Accident & Incident Detail'!$C$2:$C$3433)*($A$38='Accident & Incident Detail'!$I$2:$I$3433)*($A$41='Accident & Incident Detail'!$E$2:$E$3433))} -> 0
A42: MAA | B42: =IF(B$1=1,(SUM(B41:B41)/13),0) -> 0 | C42: =IF(C$1=1,(SUM(B41:C41)/13),0) -> 0 | D42: =IF(D$1=1,(SUM(B41:D41)/13),0) -> 0 | E42: =IF(E$1=1,(SUM(B41:E41)/13),0) -> 0 | F42: =IF(F$1=1,(SUM(B41:F41)/13),0) -> 0 | G42: =IF(G$1=1,(SUM(B41:G41)/13),0) -> 0 | H42: =IF(H$1=1,(SUM(B41:H41)/13),0) -> 0 | I42: =IF(I$1=1,(SUM(B41:I41)/13),0) -> 0 | J42: =IF(J$1=1,(SUM(B41:J41)/13),0) -> 0 | K42: =IF(K$1=1,(SUM(B41:K41)/13),0) -> 0 | L42: =IF(L$1=1,(SUM(B41:L41)/13),0) -> 0 | M42: =IF(M$1=1,(SUM(B41:M41)/13),0) -> 0 | N42: =IF(N$1=1,(SUM(B41:N41)/13),0) -> 0 | O42: =IF(O$1=1,(SUM(C41:O41)/13),0) -> 0 | P42: =IF(P$1=1,(SUM(D41:P41)/13),0) -> 0 | Q42: =IF(Q$1=1,(SUM(E41:Q41)/13),0) -> 0 | R42: =IF(R$1=1,(SUM(F41:R41)/13),0) -> 0 | S42: =IF(S$1=1,(SUM(G41:S41)/13),0) -> 0 | T42: =IF(T$1=1,(SUM(H41:T41)/13),0) -> 0 | U42: =IF(U$1=1,(SUM(I41:U41)/13),0) -> 0 | ... AN42: =IF(AN$1=1,(SUM(AB41:AN41)/13),0) -> 0
A43: Door trap | B43: {=SUM((B38='Accident & Incident Detail'!$C$2:$C$3433)*($A$38='Accident & Incident Detail'!$I$2:$I$3433)*($A$43='Accident & Incident Detail'!$E$2:$E$3433))} -> 0 | C43: {=SUM((C38='Accident & Incident Detail'!$C$2:$C$3433)*($A$38='Accident & Incident Detail'!$I$2:$I$3433)*($A$43='Accident & Incident Detail'!$E$2:$E$3433))} -> 0 | D43: {=SUM((D38='Accident & Incident Detail'!$C$2:$C$3433)*($A$38='Accident & Incident Detail'!$I$2:$I$3433)*($A$43='Accident & Incident Detail'!$E$2:$E$3433))} -> 0 | E43: {=SUM((E38='Accident & Incident Detail'!$C$2:$C$3433)*($A$38='Accident & Incident Detail'!$I$2:$I$3433)*($A$43='Accident & Incident Detail'!$E$2:$E$3433))} -> 0 | F43: {=SUM((F38='Accident & Incident Detail'!$C$2:$C$3433)*($A$38='Accident & Incident Detail'!$I$2:$I$3433)*($A$43='Accident & Incident Detail'!$E$2:$E$3433))} -> 0 | G43: {=SUM((G38='Accident & Incident Detail'!$C$2:$C$3433)*($A$38='Accident & Incident Detail'!$I$2:$I$3433)*($A$43='Accident & Incident Detail'!$E$2:$E$3433))} -> 0 | H43: {=SUM((H38='Accident & Incident Detail'!$C$2:$C$3433)*($A$38='Accident & Incident Detail'!$I$2:$I$3433)*($A$43='Accident & Incident Detail'!$E$2:$E$3433))} -> 0 | I43: {=SUM((I38='Accident & Incident Detail'!$C$2:$C$3433)*($A$38='Accident & Incident Detail'!$I$2:$I$3433)*($A$43='Accident & Incident Detail'!$E$2:$E$3433))} -> 0 | ... AN43: {=SUM((AN38='Accident & Incident Detail'!$C$2:$C$3433)*($A$38='Accident & Incident Detail'!$I$2:$I$3433)*($A$43='Accident & Incident Detail'!$E$2:$E$3433))} -> 0
...

Sheet Lookup Sheets
A1: Status | B1: Date | C1: Reporting Period | D1: Accident/ Incident Reference | E1: Accident/Incident Type | F1: Location | G1: Tram | H1: Catergory | I1: Person Type | J1: Description of incident | K1: Total Number of days Lost | L1: RIDDOR | M1: Initial Report Recived? | N1: Type of investigation carried out | O1: Investigating Manager | P1: Investigation Due | Q1: Investigation Completion date | R1: Immediate Cause | S1: Underlying Cause | T1: Recommendations Made? | U1: Comments | W1: Claim received? | X1: Investigation type
C2: 1613 | E2: Cab Indicators | G2: 106 | H2: Non-Movement | I2: n/a | O2: Alan Barclay | X2: Accident
C3: 1701 | E3: Air Conditioning | G3: 101 | H3: Staff Accident | I3: Staff | O3: Andy Roberts | X3: Assault
C4: 1702 | E4: AVL | G4: 103 | H4: INFO ONLY | I4: Public | O4: Dave Bridges | X4: Info only/SAFE
C5: 1703 | E5: Brake | G5: 104 | H5: Infrastructure | I5: Cyclist | O5: Dave Hallam | X5: Level 1
C6: 1704 | E6: Anti - social behaviour | G6: 102 | H6: Assaults | I6: Passenger | O6: Dave Marrison | X6: Level 2
C7: 1705 | E7: Burn/Scald | G7: 105 | H7: Movement | I7: Taxis | O7: David Tingle | X7: None
C8: 1706 | E8: Contact | G8: 107 | H8: Operational | I8: Eldery | O8: Emma Cooper | X8: SRD
C9: 1707 | E9: Control | G9: 108 | H9: Siemens SRD | I9: Vunrable | O9: Gary Seaborn | X9: Safety Digest
C10: 1708 | E10: Cyclist Fall | G10: 109 | I10: Third Party | O10: Glin Stanford
C11: 1709 | E11: Derailment | G11: 110 | H11: SRD | O11: Infra Dept
C12: 1710 | E12: Derailment -Multi-Car | G12: 111 | O12: IT Dept
C13: 1711 | E13: Door Open in Traffic | G13: 112 | O13: James Stewart
C14: 1712 | E14: Door Trap | G14: 113 | O14: John Cawthorn
C15: 1713 | E15: Doors | G15: 114 | O15: John Kolchuk
C16: 1801 | E16: Driver Seats | G16: 115 | O16: Josh Keeling
C17: 1802 | E17: Electricity Fire/Smoke | G17: 116 | O17: Mark Blackwell
C18: 1803 | E18: Fire | G18: 117 | O18: Neill Barraclough
C19: 1804 | E19: Headlights/Tail Lights | G19: 118 | O19: Nikolas Dobbs
C20: 1805 | E20: Heating | G20: 119 | O20: Nina Wybrant
C21: 1806 | E21: Horn/Bell | G21: 120 | O21: Rachel Bridges
C22: 1906 | E22: Physical Assault | O22: RSM Dept
C23: 1807 | E23: Incorrect VIS | G23: 121 | O23: Russ Wild
C24: 1808 | E24: Communication | G24: 122 | O24: Safety Reps
C25: 1809 | E25: Non-Tram RTC | G25: 123 | O25: Sean Cuckson
C26: 1810 | E26: Low Adhesion | G26: 124 | O26: Sharon Galloway
C27: 1907 | E27: Points | G27: 125 | O27: Andy Buckley
C28: 1811 | E28: Mirrors | G28: 201 | O28: Danielle Willey
C29: 1812 | E29: Mobility | G29: 202 | O29: Wayne Clay
E30: Near Miss - Red Light | G30: 203 | O30: James Gilbert
C31: 1813 | E31: Near Miss | G31: 204 | O31: Paul Holdsworth
C32: 1901 | E32: OHLE | G32: 205 | O32: Keith Sockett
C33: 1902 | E33: Other Accident | G33: 206 | O33: Alex Wray
C34: 1903 | E34: Other | G34: 207 | O34: Tom Harrison
C35: 1904 | E35: Pantagraph | G35: n/a
C36: 1905 | E36: Person in Cab
E37: Minor - PTC
C38: 1908 | E38: Major - PTC
C39: 1909 | E39: Radio & Communications Systems
C40: 1910 | E40: Minor - RTC
...

Sheet Summary
A1: Reporting Period | B1: 2510 | C1: Period | D1: 2510
A2: Last Period | B2: 2059
A4: Safety Performance Summary - Actual Vs Target | M4: Safety Actions | AB4: BOSRIA
B5: =B1 -> 2510 | C5: 2024/25 Period Target | D5: YTD Actual | E5: 2025/26 YTD Target | F5: 2024/2025
B6: Period Actual | F6: Target | M6: Safety Actions All | N6: 2411 | O6: 2412 | P6: 2413 | Q6: 2501 | R6: 2502 | S6: 2503 | T6: 2504 | U6: 2505 | V6: 2506 | W6: 2507 | X6: 2508 | Y6: 2509 | Z6: 2510 | AC6: 2411 | AD6: 2412 | AE6: 2413 | AF6: 2501 | AG6: 2502 | AH6: 2503 | AI6: 2504 | AJ6: 2505 | AK6: 2506 | AL6: 2507 | AM6: 2508 | AN6: 2509 | AO6: 2510
A7: Staff Accidents (Excluding LTA) | B7: =HLOOKUP(B1,Data!$AB$4:$AN$18,3) -> 1 | C7: =F7/13 -> 1.3846154 | D7: =Data!AO6 -> 22 | E7: 18 | F7: 18 | M7: Overdue | N7: =HLOOKUP(N6,Data!$O317:$AN$320,4) -> 0 | O7: =HLOOKUP(O6,Data!$O317:$AN$320,4) -> 0 | P7: =HLOOKUP(P6,Data!$O317:$AN$320,4) -> 0 | Q7: =HLOOKUP(Q6,Data!$O317:$AN$320,4) -> 1 | R7: =HLOOKUP(R6,Data!$O317:$AN$320,4) -> 1 | S7: =HLOOKUP(S6,Data!$O317:$AN$320,4) -> 0 | T7: =HLOOKUP(T6,Data!$O317:$AN$320,4) -> 2 | U7: =HLOOKUP(U6,Data!$O317:$AN$320,4) -> 0 | ... Z7: =HLOOKUP(Z6,Data!$O317:$AN$320,4) -> 3 | AB7: Overdue | AC7: =HLOOKUP(AC6,Data!$O$307:$AN$315,5) -> 0 | AD7: =HLOOKUP(AD6,Data!$O$307:$AN$315,5) -> 0 | AE7: =HLOOKUP(AE6,Data!$O$307:$AN$315,5) -> 0 | AF7: =HLOOKUP(AF6,Data!$O$307:$AN$315,5) -> 0 | AG7: =HLOOKUP(AG6,Data!$O$307:$AN$315,5) -> 1 | AH7: =HLOOKUP(AH6,Data!$O$307:$AN$315,5) -> 0 | AI7: =HLOOKUP(AI6,Data!$O$307:$AN$315,5) -> 1 | AJ7: =HLOOKUP(AJ6,Data!$O$307:$AN$315,5) -> 0 | ... AO7: =HLOOKUP(AO6,Data!$O$307:$AN$315,5) -> 3
A8: Staff Lost Time Accidents | B8: =HLOOKUP(B1,Data!$AB$4:$AN$18,4) -> 0 | C8: =F8/13 -> 0.30769231 | D8: =Data!AO7 -> 2 | E8: 5 | F8: 4 | M8: Open | N8: =HLOOKUP(N6,Data!$O$317:$AN$318,2) -> 1 | O8: =HLOOKUP(O6,Data!$O$317:$AN$318,2) -> 1 | P8: =HLOOKUP(P6,Data!$O$317:$AN$318,2) -> 0 | Q8: =HLOOKUP(Q6,Data!$O$317:$AN$318,2) -> 0 | R8: =HLOOKUP(R6,Data!$O$317:$AN$318,2) -> 0 | S8: =HLOOKUP(S6,Data!$O$317:$AN$318,2) -> 0 | T8: =HLOOKUP(T6,Data!$O$317:$AN$318,2) -> 0 | U8: =HLOOKUP(U6,Data!$O$317:$AN$318,2) -> 0 | ... Z8: =HLOOKUP(Z6,Data!$O$317:$AN$318,2) -> 1 | AB8: Open | AC8: =HLOOKUP(AC6,Data!$O$307:$AN$315,3) -> 0 | AD8: =HLOOKUP(AD6,Data!$O$307:$AN$315,3) -> 0 | AE8: =HLOOKUP(AE6,Data!$O$307:$AN$315,3) -> 0 | AF8: =HLOOKUP(AF6,Data!$O$307:$AN$315,3) -> 0 | AG8: =HLOOKUP(AG6,Data!$O$307:$AN$315,3) -> 0 | AH8: =HLOOKUP(AH6,Data!$O$307:$AN$315,3) -> 0 | AI8: =HLOOKUP(AI6,Data!$O$307:$AN$315,3) -> 0 | AJ8: =HLOOKUP(AJ6,Data!$O$307:$AN$315,3) -> 0 | ... AO8: =HLOOKUP(AO6,Data!$O$307:$AN$315,3) -> 0
A9: Assaults | B9: =HLOOKUP(B1,Data!$AB$4:$AN$18,5) -> 3 | C9: =F9/13 -> 3.4615385 | D9: =Data!AO8 -> 22 | E9: 37 | F9: 45 | M9: Closed | N9: =HLOOKUP(N6,Data!$O$317:$AN$319,3) -> 6 | O9: =HLOOKUP(O6,Data!$O$317:$AN$319,3) -> 14 | P9: =HLOOKUP(P6,Data!$O$317:$AN$319,3) -> 13 | Q9: =HLOOKUP(Q6,Data!$O$317:$AN$319,3) -> 7 | R9: =HLOOKUP(R6,Data!$O$317:$AN$319,3) -> 8 | S9: =HLOOKUP(S6,Data!$O$317:$AN$319,3) -> 4 | T9: =HLOOKUP(T6,Data!$O$317:$AN$319,3) -> 3 | U9: =HLOOKUP(U6,Data!$O$317:$AN$319,3) -> 2 | ... Z9: =HLOOKUP(Z6,Data!$O$317:$AN$319,3) -> 6 | AB9: Closed | AC9: =HLOOKUP(AC6,Data!$O$307:$AN$315,4) -> 0 | AD9: =HLOOKUP(AD6,Data!$O$307:$AN$315,4) -> 6 | AE9: =HLOOKUP(AE6,Data!$O$307:$AN$315,4) -> 2 | AF9: =HLOOKUP(AF6,Data!$O$307:$AN$315,4) -> 1 | AG9: =HLOOKUP(AG6,Data!$O$307:$AN$315,4) -> 0 | AH9: =HLOOKUP(AH6,Data!$O$307:$AN$315,4) -> 2 | AI9: =HLOOKUP(AI6,Data!$O$307:$AN$315,4) -> 0 | AJ9: =HLOOKUP(AJ6,Data!$O$307:$AN$315,4) -> 0 | ... AO9: =HLOOKUP(AO6,Data!$O$307:$AN$315,4) -> 6
A10: Movement | B10: =HLOOKUP(B1,Data!$AB$4:$AN$18,6) -> 3 | C10: =F10/13 -> 5.5384615 | D10: =Data!AO9 -> 46 | E10: 102 | F10: 72 | M10: Total | N10: =SUM(N7:N9) -> 7 | O10: =SUM(O7:O9) -> 15 | P10: =SUM(P7:P9) -> 13 | Q10: =SUM(Q7:Q9) -> 8 | R10: =SUM(R7:R9) -> 9 | S10: =SUM(S7:S9) -> 4 | T10: =SUM(T7:T9) -> 5 | U10: =SUM(U7:U9) -> 2 | ... Z10: =SUM(Z7:Z9) -> 10 | AB10: Total Anom | AC10: =HLOOKUP(AC6,Data!$O$307:$AN$315,8) -> 0 | AD10: =HLOOKUP(AD6,Data!$O$307:$AN$315,8) -> 6 | AE10: =HLOOKUP(AE6,Data!$O$307:$AN$315,8) -> 0 | AF10: =HLOOKUP(AF6,Data!$O$307:$AN$315,8) -> 0 | AG10: =HLOOKUP(AG6,Data!$O$307:$AN$315,8) -> 0 | AH10: =HLOOKUP(AH6,Data!$O$307:$AN$315,8) -> 0 | AI10: =HLOOKUP(AI6,Data!$O$307:$AN$315,8) -> 0 | AJ10: =HLOOKUP(AJ6,Data!$O$307:$AN$315,8) -> 0 | ... AO10: =HLOOKUP(AO6,Data!$O$307:$AN$315,8) -> 0
A11: Non-Movement | B11: =HLOOKUP(B1,Data!$AB$4:$AN$18,7) -> 0 | C11: =F11/13 -> 0.46153846 | D11: =Data!AO10 -> 1 | E11: 13 | F11: 6 | AB11: Total Name | AC11: =HLOOKUP(AC6,Data!$O$307:$AN$315,9) -> 0 | AD11: =HLOOKUP(AD6,Data!$O$307:$AN$315,9) -> 0 | AE11: =HLOOKUP(AE6,Data!$O$307:$AN$315,9) -> 0 | AF11: =HLOOKUP(AF6,Data!$O$307:$AN$315,9) -> 0 | AG11: =HLOOKUP(AG6,Data!$O$307:$AN$315,9) -> 0 | AH11: =HLOOKUP(AH6,Data!$O$307:$AN$315,9) -> 0 | AI11: =HLOOKUP(AI6,Data!$O$307:$AN$315,9) -> 0 | AJ11: =HLOOKUP(AJ6,Data!$O$307:$AN$315,9) -> 0 | ... AO11: =HLOOKUP(AO6,Data!$O$307:$AN$315,9) -> 0
A12: Total | B12: =HLOOKUP(B1,Data!$AB$4:$AN$18,8) -> 7 | C12: 18 | D12: =SUM(D7:D11) -> 93 | E12: =SUM(E7:E11) -> 175 | F12: =SUM(F7:F11) -> 145 | M12: Safety Action - Breakdown | AB12: Grand Total | AC12: =SUM(AC7:AC9) -> 0 | AD12: =SUM(AD7:AD9) -> 6 | AE12: =SUM(AE7:AE9) -> 2 | AF12: =SUM(AF7:AF9) -> 1 | AG12: =SUM(AG7:AG9) -> 1 | AH12: =SUM(AH7:AH9) -> 2 | AI12: =SUM(AI7:AI9) -> 1 | AJ12: =SUM(AJ7:AJ9) -> 0 | ... AO12: =SUM(AO7:AO9) -> 9
A13: Vandalism | B13: =HLOOKUP(B1,Data!$AB$4:$AN$18,9) -> 11 | C13: =F13/13 -> 8.8461538 | D13: =Data!AO12 -> 113 | E13: 106 | F13: 115 | M13: Action | S13: Overdue | U13: Open | W13: Closed | Y13: Total
A14: Low Risk Total | B14: =HLOOKUP(B1,Data!$AB$4:$AO$18,10) -> 5 | C14: =F14/13 -> 6.1538462 | D14: =Data!AO13 -> 66 | E14: 74 | F14: 80 | M14: BOSRIA Action | S14: =SUM(Data!$O$270:$AN$270) -> #N/A | U14: =SUM(Data!$O$270:$AN$270) -> #N/A | W14: =SUM(Data!$O$270:$AN$270) -> #N/A | Y14: =SUM(Data!$O$270:$AN$270) -> #N/A
A15: High Risk Total | B15: =HLOOKUP(B1,Data!$AB$4:$AO$18,11) -> 0 | C15: =F15/13 -> 0.53846154 | D15: =Data!AA14 -> 1 | E15: 6 | F15: 7 | M15: External Audit Corrective Action | S15: =SUM(Data!$O$273:$AN$273) -> 0 | U15: =SUM(Data!$O$273:$AN$273) -> 0 | W15: =SUM(Data!$O$273:$AN$273) -> 0 | Y15: =SUM(Data!$O$273:$AN$273) -> 0
A16: Near Miss Total | B16: 0 | C16: =F16/13 -> 2 | D16: =Data!AO218 -> 45 | E16: 24 | F16: 26 | M16: Safety Inspection Action | S16: =SUM(Data!$O$276:$AN$276) -> 0 | U16: =SUM(Data!$O$276:$AN$276) -> 0 | W16: =SUM(Data!$O$276:$AN$276) -> 0 | Y16: =SUM(Data!$O$276:$AN$276) -> 0
A17: BOSRIA Action | B17: 8 | C17: =F17/13 -> 7.0769231 | D17: =Data!AO309 -> 6 | E17: 85 | F17: 92 | M17: Internal Audit Corrective Action | S17: =SUM(Data!$O$279:$AN$279) -> 0 | U17: =SUM(Data!$O$279:$AN$279) -> 0 | W17: =SUM(Data!$O$279:$AN$279) -> 0 | Y17: =SUM(Data!$O$279:$AN$279) -> 0
A18: Monthly Walkarounds | B18: 0 | C18: =F18/13 -> 0.69230769 | D18: =Data!AO313 -> 0 | E18: 8 | F18: 9 | M18: Level 2 Investigation Recommendation | S18: =SUM(Data!$O$285:$AN$285) -> 0 | U18: =SUM(Data!$O$285:$AN$285) -> 0 | W18: =SUM(Data!$O$285:$AN$285) -> 0 | Y18: =SUM(Data!$O$285:$AN$285) -> 0
A19: Management Walkarounds | B19: 0 | C19: =F19/13 -> 0.30769231 | D19: =Data!AO339 -> #REF! | E19: 4 | F19: 4 | M19: Quarterly Exec Safety Meeting Action | S19: =SUM(Data!$O$288:$AN$288) -> 0 | U19: =SUM(Data!$O$288:$AN$288) -> 0 | W19: =SUM(Data!$O$288:$AN$288) -> 0 | Y19: =SUM(Data!$O$288:$AN$288) -> 0
D20: ` | M20: Quarterly Safety Representatives Meeting Action | S20: =SUM(Data!$O$291:$AN$291) -> 0 | U20: =SUM(Data!$O$291:$AN$291) -> 0 | W20: =SUM(Data!$O$291:$AN$291) -> 0 | Y20: =SUM(Data!$O$291:$AN$291) -> 0
M21: Safety Concern Action | S21: =SUM(Data!$O$294:$AN$294) -> #N/A | U21: =SUM(Data!$O$294:$AN$294) -> #N/A | W21: =SUM(Data!$O$294:$AN$294) -> #N/A | Y21: =SUM(Data!$O$294:$AN$294) -> #N/A
M22: Safety Plan Action | S22: =SUM(Data!$O$296:$AN$296) -> 0 | U22: =SUM(Data!$O$296:$AN$296) -> 0 | W22: =SUM(Data!$O$296:$AN$296) -> 0 | Y22: =SUM(Data!$O$296:$AN$296) -> 0
M23: RAIB | S23: =SUM(Data!$O$303:$Z$303) -> 0 | U23: =SUM(Data!$O$303:$Z$303) -> 0 | W23: =SUM(Data!$O$303:$Z$303) -> 0 | Y23: =SUM(Data!$O$303:$Z$303) -> 0
M24: Total | S24: =SUM(S14:T23) -> #N/A | U24: =SUM(U14:V23) -> #N/A | W24: =SUM(W14:X23) -> #N/A | Y24: =SUM(S24:X24) -> #N/A
M26: Safety Investigations
M28: Safety Investigations all | N28: 2411 | O28: 2412 | P28: 2413 | Q28: 2501 | R28: 2502 | S28: 2503 | T28: 2504 | U28: 2505 | V28: 2506 | W28: 2507 | X28: 2508 | Y28: 2509 | Z28: 2510
A29: RIDDOR | M29: Overdue | N29: =HLOOKUP(Summary!N28,Data!$O$323:$AN326,4) -> 0 | O29: =HLOOKUP(Summary!O28,Data!$O$323:$AN326,4) -> 0 | P29: =HLOOKUP(Summary!P28,Data!$O$323:$AN326,4) -> 0 | Q29: =HLOOKUP(Summary!Q28,Data!$O$323:$AN326,4) -> 0 | R29: =HLOOKUP(Summary!R28,Data!$O$323:$AN326,4) -> 0 | S29: =HLOOKUP(Summary!S28,Data!$O$323:$AN326,4) -> 0 | T29: =HLOOKUP(Summary!T28,Data!$O$323:$AN326,4) -> 4 | U29: =HLOOKUP(Summary!U28,Data!$O$323:$AN326,4) -> 6 | ... Z29: =HLOOKUP(Summary!Z28,Data!$O$323:$AN326,4) -> 8
A30: RIDDOR | M30: Open | N30: =HLOOKUP(Summary!N28,Data!$O$323:$AN324,2) -> 0 | O30: =HLOOKUP(Summary!O28,Data!$O$323:$AN324,2) -> 0 | P30: =HLOOKUP(Summary!P28,Data!$O$323:$AN324,2) -> 0 | Q30: =HLOOKUP(Summary!Q28,Data!$O$323:$AN324,2) -> 0 | R30: =HLOOKUP(Summary!R28,Data!$O$323:$AN324,2) -> 0 | S30: =HLOOKUP(Summary!S28,Data!$O$323:$AN324,2) -> 0 | T30: =HLOOKUP(Summary!T28,Data!$O$323:$AN324,2) -> 0 | U30: =HLOOKUP(Summary!U28,Data!$O$323:$AN324,2) -> 0 | ... Z30: =HLOOKUP(Summary!Z28,Data!$O$323:$AN324,2) -> 0
B31: Actual | C31: YTD | M31: Closed | N31: =HLOOKUP(Summary!N28,Data!$O$323:$AN325,3) -> 77 | O31: =HLOOKUP(Summary!O28,Data!$O$323:$AN325,3) -> 61 | P31: =HLOOKUP(Summary!P28,Data!$O$323:$AN325,3) -> 68 | Q31: =HLOOKUP(Summary!Q28,Data!$O$323:$AN325,3) -> 53 | R31: =HLOOKUP(Summary!R28,Data!$O$323:$AN325,3) -> 55 | S31: =HLOOKUP(Summary!S28,Data!$O$323:$AN325,3) -> 58 | T31: =HLOOKUP(Summary!T28,Data!$O$323:$AN325,3) -> 39 | U31: =HLOOKUP(Summary!U28,Data!$O$323:$AN325,3) -> 34 | ... Z31: =HLOOKUP(Summary!Z28,Data!$O$323:$AN325,3) -> 35
A32: RIDDOR | B32: =HLOOKUP(B1,Data!AB256:AN258,2) -> 3 | C32: =Data!AO257 -> 27 | M32: Total | N32: =SUM(N29:N31) -> 77 | O32: =SUM(O29:O31) -> 61 | P32: =SUM(P29:P31) -> 68 | Q32: =SUM(Q29:Q31) -> 53 | R32: =SUM(R29:R31) -> 55 | S32: =SUM(S29:S31) -> 58 | T32: =SUM(T29:T31) -> 43 | U32: =SUM(U29:U31) -> 40 | ... Z32: =SUM(Z29:Z31) -> 43
A35: Staff Accidents
A53: Staff Assaults
A70: Vandalism
A87: Surfing
A106: Movement Accidents
A124: Low Risk Operational Incidents
A150: High Risk Operational Incidents
A175: Near Miss
